<?xml version='1.0'?>
<sdf version='1.9'>
  <model name='simple_vehicle'>
    <pose>0 0 0.1 0 0 0</pose>
    <link name='base_link'>
      <pose>0 0 0 0 0 0</pose>
      <inertial>
        <mass>5.0</mass> <!--kg-->
        <inertia>
          <ixx>0.104167</ixx>
          <ixy>0</ixy>
          <ixz>0</ixz>
          <iyy>0.104167</iyy>
          <iyz>0</iyz>
          <izz>0.104167</izz>
        </inertia>
      </inertial>
      <collision name='base_collision'>
        <geometry>
          <box>
            <size>0.3 0.2 0.1</size> <!--长宽高单位米-->
          </box>
        </geometry>
        <surface>
          <friction>
            <ode>
              <mu>0.5</mu>
              <mu2>0.5</mu2>
            </ode>
          </friction>
        </surface>
      </collision>
      <visual name='base_visual'>
        <geometry>
          <box>
            <size>0.3 0.2 0.1</size> <!--长宽高单位米-->
          </box>
        </geometry>
        <material>
          <ambient>0.8 0.2 0.2 1</ambient>
          <diffuse>0.8 0.2 0.2 1</diffuse>
        </material>
      </visual>
    </link>

    <link name='left_wheel'>
      <pose>-0.1 0.125 0 1.5708 0 0</pose>
      <inertial>
        <mass>1.0</mass>
        <inertia>
          <ixx>0.05</ixx>
          <ixy>0</ixy>
          <ixz>0</ixz>
          <iyy>0.05</iyy>
          <iyz>0</iyz>
          <izz>0.1</izz>
        </inertia>
      </inertial>
      <collision name='left_wheel_collision'>
        <geometry>
          <cylinder>
            <radius>0.1</radius>
            <length>0.05</length>
          </cylinder>
        </geometry>
      </collision>
      <visual name='left_wheel_visual'>
        <geometry>
          <cylinder>
            <radius>0.1</radius>
            <length>0.05</length>
          </cylinder>
        </geometry>
        <material>
          <ambient>0.3 0.3 0.3 1</ambient>
          <diffuse>0.3 0.3 0.3 1</diffuse>
        </material>
      </visual>      
    </link>

    <joint name='left_wheel_joint' type='revolute'>
      <pose>-0.1 0 0 0 0 0</pose>
      <parent>base_link</parent>
      <child>left_wheel</child>
      <axis>
        <xyz>0 1 0</xyz> <!--Y轴为旋转轴-->
        <limit>
          <lower>-1e9</lower>
          <upper>1e9</upper>
        </limit>
      </axis>
    </joint>

    <link name='right_wheel'>
      <pose>-0.1 -0.125 0 1.5708 0 0</pose>
      <inertial>
        <mass>1.0</mass>
        <inertia>
          <ixx>0.05</ixx>
          <ixy>0</ixy>
          <ixz>0</ixz>
          <iyy>0.05</iyy>
          <iyz>0</iyz>
          <izz>0.1</izz>
        </inertia>
      </inertial>
      <collision name='right_wheel_collision'>
        <geometry>
          <cylinder>
            <radius>0.1</radius>
            <length>0.05</length>
          </cylinder>
        </geometry>
      </collision>
      <visual name='right_wheel_visual'>
        <geometry>
          <cylinder>
            <radius>0.1</radius>
            <length>0.05</length>
          </cylinder>
        </geometry>
        <material>
          <ambient>0.3 0.3 0.3 1</ambient>
          <diffuse>0.3 0.3 0.3 1</diffuse>
        </material>
      </visual>      
    </link>

    <joint name='right_wheel_joint' type='revolute'>
      <pose>-0.1 0 0 0 0 0</pose>
      <parent>base_link</parent>
      <child>right_wheel</child>
      <axis>
        <xyz>0 1 0</xyz> <!--Y轴为旋转轴-->
        <limit>
          <lower>-1e9</lower>
          <upper>1e9</upper>
        </limit>
      </axis>
    </joint>

  </model>
</sdf>